<?xml version="1.0" ?>
<!-- =================================================================================== -->
<!-- |    This document was autogenerated by xacro from /home/peraspera/irene_ws/src/mario_so2_description/urdf/mario_so2.xacro | -->
<!-- |    EDITING THIS FILE BY HAND IS NOT RECOMMENDED                                 | -->
<!-- =================================================================================== -->
<robot name="mario_so2">
    <material name="silver">
        <color rgba="0.700 0.700 0.700 1.000" />
    </material>
    <transmission name="arm_01_joint_06_tran">
        <type>transmission_interface/SimpleTransmission</type>
        <joint name="arm_01_joint_06">
            <hardwareInterface>hardware_interface/PositionJointInterface</hardwareInterface>
        </joint>
        <actuator name="arm_01_joint_06_actr">
            <hardwareInterface>hardware_interface/PositionJointInterface</hardwareInterface>
            <mechanicalReduction>1</mechanicalReduction>
        </actuator>
    </transmission>
    <transmission name="arm_01_joint_05_tran">
        <type>transmission_interface/SimpleTransmission</type>
        <joint name="arm_01_joint_05">
            <hardwareInterface>hardware_interface/PositionJointInterface</hardwareInterface>
        </joint>
        <actuator name="arm_01_joint_05_actr">
            <hardwareInterface>hardware_interface/PositionJointInterface</hardwareInterface>
            <mechanicalReduction>1</mechanicalReduction>
        </actuator>
    </transmission>
    <transmission name="arm_01_joint_04_tran">
        <type>transmission_interface/SimpleTransmission</type>
        <joint name="arm_01_joint_04">
            <hardwareInterface>hardware_interface/PositionJointInterface</hardwareInterface>
        </joint>
        <actuator name="arm_01_joint_04_actr">
            <hardwareInterface>hardware_interface/PositionJointInterface</hardwareInterface>
            <mechanicalReduction>1</mechanicalReduction>
        </actuator>
    </transmission>
    <transmission name="arm_01_joint_03_tran">
        <type>transmission_interface/SimpleTransmission</type>
        <joint name="arm_01_joint_03">
            <hardwareInterface>hardware_interface/PositionJointInterface</hardwareInterface>
        </joint>
        <actuator name="arm_01_joint_03_actr">
            <hardwareInterface>hardware_interface/PositionJointInterface</hardwareInterface>
            <mechanicalReduction>1</mechanicalReduction>
        </actuator>
    </transmission>
    <transmission name="arm_01_joint_02_tran">
        <type>transmission_interface/SimpleTransmission</type>
        <joint name="arm_01_joint_02">
            <hardwareInterface>hardware_interface/PositionJointInterface</hardwareInterface>
        </joint>
        <actuator name="arm_01_joint_02_actr">
            <hardwareInterface>hardware_interface/PositionJointInterface</hardwareInterface>
            <mechanicalReduction>1</mechanicalReduction>
        </actuator>
    </transmission>
    <transmission name="arm_01_joint_01_tran">
        <type>transmission_interface/SimpleTransmission</type>
        <joint name="arm_01_joint_01">
            <hardwareInterface>hardware_interface/PositionJointInterface</hardwareInterface>
        </joint>
        <actuator name="arm_01_joint_01_actr">
            <hardwareInterface>hardware_interface/PositionJointInterface</hardwareInterface>
            <mechanicalReduction>1</mechanicalReduction>
        </actuator>
    </transmission>
    <transmission name="arm_02_joint_06_tran">
        <type>transmission_interface/SimpleTransmission</type>
        <joint name="arm_02_joint_06">
            <hardwareInterface>hardware_interface/PositionJointInterface</hardwareInterface>
        </joint>
        <actuator name="arm_02_joint_06_actr">
            <hardwareInterface>hardware_interface/PositionJointInterface</hardwareInterface>
            <mechanicalReduction>1</mechanicalReduction>
        </actuator>
    </transmission>
    <transmission name="arm_02_joint_05_tran">
        <type>transmission_interface/SimpleTransmission</type>
        <joint name="arm_02_joint_05">
            <hardwareInterface>hardware_interface/PositionJointInterface</hardwareInterface>
        </joint>
        <actuator name="arm_02_joint_05_actr">
            <hardwareInterface>hardware_interface/PositionJointInterface</hardwareInterface>
            <mechanicalReduction>1</mechanicalReduction>
        </actuator>
    </transmission>
    <transmission name="arm_02_joint_04_tran">
        <type>transmission_interface/SimpleTransmission</type>
        <joint name="arm_02_joint_04">
            <hardwareInterface>hardware_interface/PositionJointInterface</hardwareInterface>
        </joint>
        <actuator name="arm_02_joint_04_actr">
            <hardwareInterface>hardware_interface/PositionJointInterface</hardwareInterface>
            <mechanicalReduction>1</mechanicalReduction>
        </actuator>
    </transmission>
    <transmission name="arm_02_joint_03_tran">
        <type>transmission_interface/SimpleTransmission</type>
        <joint name="arm_02_joint_03">
            <hardwareInterface>hardware_interface/PositionJointInterface</hardwareInterface>
        </joint>
        <actuator name="arm_02_joint_03_actr">
            <hardwareInterface>hardware_interface/PositionJointInterface</hardwareInterface>
            <mechanicalReduction>1</mechanicalReduction>
        </actuator>
    </transmission>
    <transmission name="arm_02_joint_02_tran">
        <type>transmission_interface/SimpleTransmission</type>
        <joint name="arm_02_joint_02">
            <hardwareInterface>hardware_interface/PositionJointInterface</hardwareInterface>
        </joint>
        <actuator name="arm_02_joint_02_actr">
            <hardwareInterface>hardware_interface/PositionJointInterface</hardwareInterface>
            <mechanicalReduction>1</mechanicalReduction>
        </actuator>
    </transmission>
    <transmission name="arm_02_joint_01_tran">
        <type>transmission_interface/SimpleTransmission</type>
        <joint name="arm_02_joint_01">
            <hardwareInterface>hardware_interface/PositionJointInterface</hardwareInterface>
        </joint>
        <actuator name="arm_02_joint_01_actr">
            <hardwareInterface>hardware_interface/PositionJointInterface</hardwareInterface>
            <mechanicalReduction>1</mechanicalReduction>
        </actuator>
    </transmission>
    <transmission name="arm_03_joint_06_tran">
        <type>transmission_interface/SimpleTransmission</type>
        <joint name="arm_03_joint_06">
            <hardwareInterface>hardware_interface/PositionJointInterface</hardwareInterface>
        </joint>
        <actuator name="arm_03_joint_06_actr">
            <hardwareInterface>hardware_interface/PositionJointInterface</hardwareInterface>
            <mechanicalReduction>1</mechanicalReduction>
        </actuator>
    </transmission>
    <transmission name="arm_03_joint_05_tran">
        <type>transmission_interface/SimpleTransmission</type>
        <joint name="arm_03_joint_05">
            <hardwareInterface>hardware_interface/PositionJointInterface</hardwareInterface>
        </joint>
        <actuator name="arm_03_joint_05_actr">
            <hardwareInterface>hardware_interface/PositionJointInterface</hardwareInterface>
            <mechanicalReduction>1</mechanicalReduction>
        </actuator>
    </transmission>
    <transmission name="arm_03_joint_04_tran">
        <type>transmission_interface/SimpleTransmission</type>
        <joint name="arm_03_joint_04">
            <hardwareInterface>hardware_interface/PositionJointInterface</hardwareInterface>
        </joint>
        <actuator name="arm_03_joint_04_actr">
            <hardwareInterface>hardware_interface/PositionJointInterface</hardwareInterface>
            <mechanicalReduction>1</mechanicalReduction>
        </actuator>
    </transmission>
    <transmission name="arm_03_joint_03_tran">
        <type>transmission_interface/SimpleTransmission</type>
        <joint name="arm_03_joint_03">
            <hardwareInterface>hardware_interface/PositionJointInterface</hardwareInterface>
        </joint>
        <actuator name="arm_03_joint_03_actr">
            <hardwareInterface>hardware_interface/PositionJointInterface</hardwareInterface>
            <mechanicalReduction>1</mechanicalReduction>
        </actuator>
    </transmission>
    <transmission name="arm_03_joint_02_tran">
        <type>transmission_interface/SimpleTransmission</type>
        <joint name="arm_03_joint_02">
            <hardwareInterface>hardware_interface/PositionJointInterface</hardwareInterface>
        </joint>
        <actuator name="arm_03_joint_02_actr">
            <hardwareInterface>hardware_interface/PositionJointInterface</hardwareInterface>
            <mechanicalReduction>1</mechanicalReduction>
        </actuator>
    </transmission>
    <transmission name="arm_03_joint_01_tran">
        <type>transmission_interface/SimpleTransmission</type>
        <joint name="arm_03_joint_01">
            <hardwareInterface>hardware_interface/PositionJointInterface</hardwareInterface>
        </joint>
        <actuator name="arm_03_joint_01_actr">
            <hardwareInterface>hardware_interface/PositionJointInterface</hardwareInterface>
            <mechanicalReduction>1</mechanicalReduction>
        </actuator>
    </transmission>
    <gazebo>
        <plugin filename="libgazebo_ros_control.so" name="control" />
        <plugin name="gazebo_ros_control">
            <robotNamespace>/</robotNamespace>
        </plugin>
    </gazebo>
    <gazebo reference="base_link">
        <material>Gazebo/Silver</material>
        <mu1>0.2</mu1>
        <mu2>0.2</mu2>
        <selfCollide>true</selfCollide>
        <gravity>true</gravity>
    </gazebo>
    <gazebo reference="arm_02_dock_1">
        <material>Gazebo/Silver</material>
        <mu1>0.2</mu1>
        <mu2>0.2</mu2>
        <selfCollide>true</selfCollide>
    </gazebo>
    <gazebo reference="arm_02_link_06_1">
        <material>Gazebo/Silver</material>
        <mu1>0.2</mu1>
        <mu2>0.2</mu2>
        <selfCollide>true</selfCollide>
    </gazebo>
    <gazebo reference="arm_02_link_05_1">
        <material>Gazebo/Silver</material>
        <mu1>0.2</mu1>
        <mu2>0.2</mu2>
        <selfCollide>true</selfCollide>
    </gazebo>
    <gazebo reference="arm_02_link_04_1">
        <material>Gazebo/Silver</material>
        <mu1>0.2</mu1>
        <mu2>0.2</mu2>
        <selfCollide>true</selfCollide>
    </gazebo>
    <gazebo reference="arm_02_link_03_1">
        <material>Gazebo/Silver</material>
        <mu1>0.2</mu1>
        <mu2>0.2</mu2>
        <selfCollide>true</selfCollide>
    </gazebo>
    <gazebo reference="arm_02_link_02_1">
        <material>Gazebo/Silver</material>
        <mu1>0.2</mu1>
        <mu2>0.2</mu2>
        <selfCollide>true</selfCollide>
    </gazebo>
    <gazebo reference="arm_02_link_01_1">
        <material>Gazebo/Silver</material>
        <mu1>0.2</mu1>
        <mu2>0.2</mu2>
        <selfCollide>true</selfCollide>
    </gazebo>
    <gazebo reference="arm_03_dock_1">
        <material>Gazebo/Silver</material>
        <mu1>0.2</mu1>
        <mu2>0.2</mu2>
        <selfCollide>true</selfCollide>
    </gazebo>
    <gazebo reference="arm_03_link_06_1">
        <material>Gazebo/Silver</material>
        <mu1>0.2</mu1>
        <mu2>0.2</mu2>
        <selfCollide>true</selfCollide>
    </gazebo>
    <gazebo reference="arm_03_link_05_1">
        <material>Gazebo/Silver</material>
        <mu1>0.2</mu1>
        <mu2>0.2</mu2>
        <selfCollide>true</selfCollide>
    </gazebo>
    <gazebo reference="arm_03_link_04_1">
        <material>Gazebo/Silver</material>
        <mu1>0.2</mu1>
        <mu2>0.2</mu2>
        <selfCollide>true</selfCollide>
    </gazebo>
    <gazebo reference="arm_03_link_03_1">
        <material>Gazebo/Silver</material>
        <mu1>0.2</mu1>
        <mu2>0.2</mu2>
        <selfCollide>true</selfCollide>
    </gazebo>
    <gazebo reference="arm_03_link_02_1">
        <material>Gazebo/Silver</material>
        <mu1>0.2</mu1>
        <mu2>0.2</mu2>
        <selfCollide>true</selfCollide>
    </gazebo>
    <gazebo reference="arm_03_link_01_1">
        <material>Gazebo/Silver</material>
        <mu1>0.2</mu1>
        <mu2>0.2</mu2>
        <selfCollide>true</selfCollide>
    </gazebo>
    <gazebo reference="arm_01_dock_1">
        <material>Gazebo/Silver</material>
        <mu1>0.2</mu1>
        <mu2>0.2</mu2>
        <selfCollide>true</selfCollide>
    </gazebo>
    <gazebo reference="arm_01_link_06_1">
        <material>Gazebo/Silver</material>
        <mu1>0.2</mu1>
        <mu2>0.2</mu2>
        <selfCollide>true</selfCollide>
    </gazebo>
    <gazebo reference="arm_01_link_05_1">
        <material>Gazebo/Silver</material>
        <mu1>0.2</mu1>
        <mu2>0.2</mu2>
        <selfCollide>true</selfCollide>
    </gazebo>
    <gazebo reference="arm_01_link_04_1">
        <material>Gazebo/Silver</material>
        <mu1>0.2</mu1>
        <mu2>0.2</mu2>
        <selfCollide>true</selfCollide>
    </gazebo>
    <gazebo reference="arm_01_link_03_1">
        <material>Gazebo/Silver</material>
        <mu1>0.2</mu1>
        <mu2>0.2</mu2>
        <selfCollide>true</selfCollide>
    </gazebo>
    <gazebo reference="arm_01_link_02_1">
        <material>Gazebo/Silver</material>
        <mu1>0.2</mu1>
        <mu2>0.2</mu2>
        <selfCollide>true</selfCollide>
    </gazebo>
    <gazebo reference="arm_01_link_01_1">
        <material>Gazebo/Silver</material>
        <mu1>0.2</mu1>
        <mu2>0.2</mu2>
        <selfCollide>true</selfCollide>
    </gazebo>
    <gazebo reference="arm_01_link_00_1">
        <material>Gazebo/Silver</material>
        <mu1>0.2</mu1>
        <mu2>0.2</mu2>
        <selfCollide>true</selfCollide>
    </gazebo>
    <gazebo reference="arm_03_link_00_1">
        <material>Gazebo/Silver</material>
        <mu1>0.2</mu1>
        <mu2>0.2</mu2>
        <selfCollide>true</selfCollide>
    </gazebo>
    <gazebo reference="arm_02_link_00_1">
        <material>Gazebo/Silver</material>
        <mu1>0.2</mu1>
        <mu2>0.2</mu2>
        <selfCollide>true</selfCollide>
    </gazebo>
    <link name="dummy_link">
        <visual>
            <!-- <geometry>
      <sphere radius="0.1"/>
    </geometry>   -->
        </visual>
        <collision>
            <geometry>
                <cylinder length="0.05" radius="0.1" />
            </geometry>
        </collision>
        <inertial>
            <mass value="0.1" />
            <origin xyz="0 0 0" rpy="0 0 0" />
            <inertia ixx="0.03" iyy="0.03" izz="0.03" ixy="0.0" ixz="0.0" iyz="0.0" />
        </inertial>
    </link>
    <link name="base_link">
        <inertial>
            <origin rpy="0 0 0" xyz="0.0010000000000137455 0.595339900070785 1.460901992118656" />
            <mass value="13.472578526765847" />
            <inertia ixx="0.568265" ixy="-0.0" ixz="-0.0" iyy="0.36191" iyz="0.0" izz="0.36191" />
        </inertial>
        <visual>
            <origin rpy="0 0 0" xyz="0 0 0" />
            <geometry>
                <mesh filename="package://mario_so2_description/meshes/base_link.stl" scale="0.001 0.001 0.001" />
            </geometry>
            <material name="silver" />
        </visual>
        <collision>
            <origin rpy="0 0 0" xyz="0 0 0" />
            <geometry>
                <mesh filename="package://mario_so2_description/meshes/base_link.stl" scale="0.001 0.001 0.001" />
            </geometry>
        </collision>
    </link>
    <joint name="dummy_joint" type="fixed">
        <origin rpy="0 0 0" xyz="0.0 0.0 0.0" />
        <parent link="dummy_link" />
        <child link="base_link" />
    </joint>
    <link name="arm_01_dock_1" self_collide="false">
        <inertial>
            <origin rpy="0 0 0" xyz="4.130804489454218e-05 -9.994297911486427e-08 0.01137523033735599" />
            <mass value="0.08663474027437225" />
            <inertia ixx="3.1e-05" ixy="-0.0" ixz="0.0" iyy="3e-05" iyz="0.0" izz="5.2e-05" />
        </inertial>
        <visual>
            <origin rpy="0 0 0" xyz="-0.001 -0.59634 -2.902983" />
            <geometry>
                <mesh filename="package://mario_so2_description/meshes/arm_01_dock_1.stl" scale="0.001 0.001 0.001" />
            </geometry>
            <material name="silver" />
        </visual>
        <collision>
            <origin rpy="0 0 0" xyz="-0.001 -0.59634 -2.902983" />
            <geometry>
                <mesh filename="package://mario_so2_description/meshes/arm_01_dock_1.stl" scale="0.001 0.001 0.001" />
            </geometry>
        </collision>
    </link>
    <link name="arm_01_link_06_1">
        <inertial>
            <origin rpy="0 0 0" xyz="2.2254116952002967e-14 -9.992921334855964e-08 0.03075011594588606" />
            <mass value="0.512001062718799" />
            <inertia ixx="0.000481" ixy="-0.0" ixz="0.0" iyy="0.000481" iyz="0.0" izz="0.00064" />
        </inertial>
        <visual>
            <origin rpy="0 0 0" xyz="-0.001 -0.59634 -2.841483" />
            <geometry>
                <mesh filename="package://mario_so2_description/meshes/arm_01_link_06_1.stl" scale="0.001 0.001 0.001" />
            </geometry>
            <material name="silver" />
        </visual>
        <collision>
            <origin rpy="0 0 0" xyz="-0.001 -0.59634 -2.841483" />
            <geometry>
                <mesh filename="package://mario_so2_description/meshes/arm_01_link_06_1.stl" scale="0.001 0.001 0.001" />
            </geometry>
        </collision>
    </link>
    <link name="arm_01_link_05_1">
        <inertial>
            <origin rpy="0 0 0" xyz="2.1614654510671016e-14 0.016214762343154 0.03500374657024796" />
            <mass value="0.6881071421127011" />
            <inertia ixx="0.001936" ixy="-0.0" ixz="0.0" iyy="0.002005" iyz="0.000344" izz="0.000767" />
        </inertial>
        <visual>
            <origin rpy="0 0 0" xyz="-0.001 -0.59634 -2.735583" />
            <geometry>
                <mesh filename="package://mario_so2_description/meshes/arm_01_link_05_1.stl" scale="0.001 0.001 0.001" />
            </geometry>
            <material name="silver" />
        </visual>
        <collision>
            <origin rpy="0 0 0" xyz="-0.001 -0.59634 -2.735583" />
            <geometry>
                <mesh filename="package://mario_so2_description/meshes/arm_01_link_05_1.stl" scale="0.001 0.001 0.001" />
            </geometry>
        </collision>
    </link>
    <link name="arm_01_link_04_1">
        <inertial>
            <origin rpy="0 0 0" xyz="1.51766521821414e-05 -0.01610484198962192 0.07035754068605904" />
            <mass value="0.7020791981272467" />
            <inertia ixx="0.001945" ixy="0.0" ixz="0.0" iyy="0.002018" iyz="0.000346" izz="0.000767" />
        </inertial>
        <visual>
            <origin rpy="0 0 0" xyz="-0.001 -0.59634 -2.629683" />
            <geometry>
                <mesh filename="package://mario_so2_description/meshes/arm_01_link_04_1.stl" scale="0.001 0.001 0.001" />
            </geometry>
            <material name="silver" />
        </visual>
        <collision>
            <origin rpy="0 0 0" xyz="-0.001 -0.59634 -2.629683" />
            <geometry>
                <mesh filename="package://mario_so2_description/meshes/arm_01_link_04_1.stl" scale="0.001 0.001 0.001" />
            </geometry>
        </collision>
    </link>
    <link name="arm_01_link_03_1">
        <inertial>
            <origin rpy="0 0 0" xyz="2.021126321860578e-14 0.021007460364998343 0.08504656118811038" />
            <mass value="0.997405593886483" />
            <inertia ixx="0.008723" ixy="-0.0" ixz="0.0" iyy="0.008725" iyz="0.00095" izz="0.001152" />
        </inertial>
        <visual>
            <origin rpy="0 0 0" xyz="-0.001 -0.58994 -2.421283" />
            <geometry>
                <mesh filename="package://mario_so2_description/meshes/arm_01_link_03_1.stl" scale="0.001 0.001 0.001" />
            </geometry>
            <material name="silver" />
        </visual>
        <collision>
            <origin rpy="0 0 0" xyz="-0.001 -0.58994 -2.421283" />
            <geometry>
                <mesh filename="package://mario_so2_description/meshes/arm_01_link_03_1.stl" scale="0.001 0.001 0.001" />
            </geometry>
        </collision>
    </link>
    <link name="arm_01_link_02_1">
        <inertial>
            <origin rpy="0 0 0" xyz="1.8630496451121914e-14 -0.03418881162303633 0.20500011594588496" />
            <mass value="1.9698176425610354" />
            <inertia ixx="0.049229" ixy="-0.0" ixz="-0.0" iyy="0.050345" iyz="0.0" izz="0.001889" />
        </inertial>
        <visual>
            <origin rpy="0 0 0" xyz="-0.001 -0.58994 -2.011283" />
            <geometry>
                <mesh filename="package://mario_so2_description/meshes/arm_01_link_02_1.stl" scale="0.001 0.001 0.001" />
            </geometry>
            <material name="silver" />
        </visual>
        <collision>
            <origin rpy="0 0 0" xyz="-0.001 -0.58994 -2.011283" />
            <geometry>
                <mesh filename="package://mario_so2_description/meshes/arm_01_link_02_1.stl" scale="0.001 0.001 0.001" />
            </geometry>
        </collision>
    </link>
    <link name="arm_01_link_01_1">
        <inertial>
            <origin rpy="0 0 0" xyz="6.394930572714216e-09 0.013243404228856392 0.0817063972213945" />
            <mass value="0.770115514016459" />
            <inertia ixx="0.002717" ixy="0.0" ixz="0.0" iyy="0.002827" iyz="-0.000327" izz="0.000757" />
        </inertial>
        <visual>
            <origin rpy="0 0 0" xyz="-0.001 -0.59534 -1.882883" />
            <geometry>
                <mesh filename="package://mario_so2_description/meshes/arm_01_link_01_1.stl" scale="0.001 0.001 0.001" />
            </geometry>
            <material name="silver" />
        </visual>
        <collision>
            <origin rpy="0 0 0" xyz="-0.001 -0.59534 -1.882883" />
            <geometry>
                <mesh filename="package://mario_so2_description/meshes/arm_01_link_01_1.stl" scale="0.001 0.001 0.001" />
            </geometry>
        </collision>
    </link>
    <link name="arm_01_link_00_1">
        <inertial>
            <origin rpy="0 0 0" xyz="1.6445395392694628e-14 -9.992921468082727e-08 0.0782001159458845" />
            <mass value="1.302064491206825" />
            <inertia ixx="0.003468" ixy="-0.0" ixz="0.0" iyy="0.003468" iyz="-0.0" izz="0.001628" />
        </inertial>
        <visual>
            <origin rpy="0 0 0" xyz="-0.001 -0.59534 -1.726483" />
            <geometry>
                <mesh filename="package://mario_so2_description/meshes/arm_01_link_00_1.stl" scale="0.001 0.001 0.001" />
            </geometry>
            <material name="silver" />
        </visual>
        <collision>
            <origin rpy="0 0 0" xyz="-0.001 -0.59534 -1.726483" />
            <geometry>
                <mesh filename="package://mario_so2_description/meshes/arm_01_link_00_1.stl" scale="0.001 0.001 0.001" />
            </geometry>
        </collision>
    </link>
    <link name="arm_02_dock_1" self_collide="false">
        <inertial>
            <origin rpy="0 0 0" xyz="-2.9186704699881715e-05 -2.91810067366062e-05 -0.011374866043244669" />
            <mass value="0.08663439746489035" />
            <inertia ixx="3e-05" ixy="0.0" ixz="0.0" iyy="3e-05" iyz="0.0" izz="5.2e-05" />
        </inertial>
        <visual>
            <origin rpy="0 0 0" xyz="0.0 0.0 -0.3372" />
            <geometry>
                <mesh filename="package://mario_so2_description/meshes/arm_02_dock_1.stl" scale="0.001 0.001 0.001" />
            </geometry>
            <material name="silver" />
        </visual>
        <collision>
            <origin rpy="0 0 0" xyz="0.0 0.0 -0.3372" />
            <geometry>
                <mesh filename="package://mario_so2_description/meshes/arm_02_dock_1.stl" scale="0.001 0.001 0.001" />
            </geometry>
        </collision>
    </link>
    <link name="arm_02_link_06_1">
        <inertial>
            <origin rpy="0 0 0" xyz="-9.774125953043723e-16 -3.552713678800501e-16 -0.030749839251724587" />
            <mass value="0.5120010627188" />
            <inertia ixx="0.000481" ixy="0.0" ixz="0.0" iyy="0.000481" iyz="0.0" izz="0.00064" />
        </inertial>
        <visual>
            <origin rpy="0 0 0" xyz="0.0 -0.0 -0.3987" />
            <geometry>
                <mesh filename="package://mario_so2_description/meshes/arm_02_link_06_1.stl" scale="0.001 0.001 0.001" />
            </geometry>
            <material name="silver" />
        </visual>
        <collision>
            <origin rpy="0 0 0" xyz="0.0 -0.0 -0.3987" />
            <geometry>
                <mesh filename="package://mario_so2_description/meshes/arm_02_link_06_1.stl" scale="0.001 0.001 0.001" />
            </geometry>
        </collision>
    </link>
    <link name="arm_02_link_05_1">
        <inertial>
            <origin rpy="0 0 0" xyz="-0.01621486220125651 2.3092638912203257e-16 -0.035003456293430824" />
            <mass value="0.6881065314959495" />
            <inertia ixx="0.002005" ixy="0.0" ixz="0.000344" iyy="0.001936" iyz="0.0" izz="0.000767" />
        </inertial>
        <visual>
            <origin rpy="0 0 0" xyz="-0.0 -0.0 -0.5046" />
            <geometry>
                <mesh filename="package://mario_so2_description/meshes/arm_02_link_05_1.stl" scale="0.001 0.001 0.001" />
            </geometry>
            <material name="silver" />
        </visual>
        <collision>
            <origin rpy="0 0 0" xyz="-0.0 -0.0 -0.5046" />
            <geometry>
                <mesh filename="package://mario_so2_description/meshes/arm_02_link_05_1.stl" scale="0.001 0.001 0.001" />
            </geometry>
        </collision>
    </link>
    <link name="arm_02_link_04_1">
        <inertial>
            <origin rpy="0 0 0" xyz="0.016104633335673482 0.012202219627462504 -0.0692910057608298" />
            <mass value="0.7020704942394854" />
            <inertia ixx="0.002018" ixy="-6e-05" ixz="0.00034" iyy="0.00191" iyz="0.000202" izz="0.000803" />
        </inertial>
        <visual>
            <origin rpy="0 0 0" xyz="-0.0 0.018389 -0.608891" />
            <geometry>
                <mesh filename="package://mario_so2_description/meshes/arm_02_link_04_1.stl" scale="0.001 0.001 0.001" />
            </geometry>
            <material name="silver" />
        </visual>
        <collision>
            <origin rpy="0 0 0" xyz="-0.0 0.018389 -0.608891" />
            <geometry>
                <mesh filename="package://mario_so2_description/meshes/arm_02_link_04_1.stl" scale="0.001 0.001 0.001" />
            </geometry>
        </collision>
    </link>
    <link name="arm_02_link_03_1">
        <inertial>
            <origin rpy="0 0 0" xyz="-0.021007560363107122 0.014768538004174867 -0.08375416118603274" />
            <mass value="0.9974055974174101" />
            <inertia ixx="0.008725" ixy="-0.000165" ixz="0.000936" iyy="0.008495" iyz="0.001295" izz="0.00138" />
        </inertial>
        <visual>
            <origin rpy="0 0 0" xyz="-0.0064 0.054578 -0.814125" />
            <geometry>
                <mesh filename="package://mario_so2_description/meshes/arm_02_link_03_1.stl" scale="0.001 0.001 0.001" />
            </geometry>
            <material name="silver" />
        </visual>
        <collision>
            <origin rpy="0 0 0" xyz="-0.0064 0.054578 -0.814125" />
            <geometry>
                <mesh filename="package://mario_so2_description/meshes/arm_02_link_03_1.stl" scale="0.001 0.001 0.001" />
            </geometry>
        </collision>
    </link>
    <link name="arm_02_link_02_1">
        <inertial>
            <origin rpy="0 0 0" xyz="0.03418871169382718 -0.08663687858386163 -0.18579266613748313" />
            <mass value="1.969817642560595" />
            <inertia ixx="0.050345" ixy="-0.0" ixz="0.0" iyy="0.040774" iyz="-0.018132" izz="0.010344" />
        </inertial>
        <visual>
            <origin rpy="0 0 0" xyz="-0.0064 -0.118696 -1.185711" />
            <geometry>
                <mesh filename="package://mario_so2_description/meshes/arm_02_link_02_1.stl" scale="0.001 0.001 0.001" />
            </geometry>
            <material name="silver" />
        </visual>
        <collision>
            <origin rpy="0 0 0" xyz="-0.0064 -0.118696 -1.185711" />
            <geometry>
                <mesh filename="package://mario_so2_description/meshes/arm_02_link_02_1.stl" scale="0.001 0.001 0.001" />
            </geometry>
        </collision>
    </link>
    <link name="arm_02_link_01_1">
        <inertial>
            <origin rpy="0 0 0" xyz="-0.013243511469972165 -0.07076019143894366 -0.040852712236645106" />
            <mass value="0.7701153946406074" />
            <inertia ixx="0.002827" ixy="-0.000283" ixz="-0.000163" iyy="0.001247" iyz="-0.000849" izz="0.002227" />
        </inertial>
        <visual>
            <origin rpy="0 0 0" xyz="-0.001 -0.229894 -1.249911" />
            <geometry>
                <mesh filename="package://mario_so2_description/meshes/arm_02_link_01_1.stl" scale="0.001 0.001 0.001" />
            </geometry>
            <material name="silver" />
        </visual>
        <collision>
            <origin rpy="0 0 0" xyz="-0.001 -0.229894 -1.249911" />
            <geometry>
                <mesh filename="package://mario_so2_description/meshes/arm_02_link_01_1.stl" scale="0.001 0.001 0.001" />
            </geometry>
        </collision>
    </link>
    <link name="arm_02_link_00_1">
        <inertial>
            <origin rpy="0 0 0" xyz="1.1613756831230226e-14 -0.06772328650515863 -0.03909956979495832" />
            <mass value="1.3020644912068255" />
            <inertia ixx="0.003468" ixy="-0.0" ixz="0.0" iyy="0.002088" iyz="-0.000797" izz="0.003008" />
        </inertial>
        <visual>
            <origin rpy="0 0 0" xyz="-0.001 -0.36534 -1.328111" />
            <geometry>
                <mesh filename="package://mario_so2_description/meshes/arm_02_link_00_1.stl" scale="0.001 0.001 0.001" />
            </geometry>
            <material name="silver" />
        </visual>
        <collision>
            <origin rpy="0 0 0" xyz="-0.001 -0.36534 -1.328111" />
            <geometry>
                <mesh filename="package://mario_so2_description/meshes/arm_02_link_00_1.stl" scale="0.001 0.001 0.001" />
            </geometry>
        </collision>
    </link>
    <link name="arm_03_dock_1" self_collide="false">
        <inertial>
            <origin rpy="0 0 0" xyz="-0.5963108374408784 0.23717058925821155 -0.4222969464714996" />
            <mass value="0.08663484175253014" />
            <inertia ixx="3e-05" ixy="-0.0" ixz="-0.0" iyy="3e-05" iyz="0.0" izz="5.2e-05" />
        </inertial>
        <visual>
            <origin rpy="0 0 0" xyz="-0.59634 -0.95348 -0.748122" />
            <geometry>
                <mesh filename="package://mario_so2_description/meshes/arm_03_dock_1.stl" scale="0.001 0.001 0.001" />
            </geometry>
            <material name="silver" />
        </visual>
        <collision>
            <origin rpy="0 0 0" xyz="-0.59634 -0.95348 -0.748122" />
            <geometry>
                <mesh filename="package://mario_so2_description/meshes/arm_03_dock_1.stl" scale="0.001 0.001 0.001" />
            </geometry>
        </collision>
    </link>
    <link name="arm_03_link_06_1">
        <inertial>
            <origin rpy="0 0 0" xyz="5.191125307391076e-15 -1.9985843469072506e-07 -0.030749839251732247" />
            <mass value="0.5120010627187991" />
            <inertia ixx="0.000481" ixy="-0.0" ixz="0.0" iyy="0.000481" iyz="0.0" izz="0.00064" />
        </inertial>
        <visual>
            <origin rpy="0 0 0" xyz="-0.0 -1.19068 -0.3987" />
            <geometry>
                <mesh filename="package://mario_so2_description/meshes/arm_03_link_06_1.stl" scale="0.001 0.001 0.001" />
            </geometry>
            <material name="silver" />
        </visual>
        <collision>
            <origin rpy="0 0 0" xyz="-0.0 -1.19068 -0.3987" />
            <geometry>
                <mesh filename="package://mario_so2_description/meshes/arm_03_link_06_1.stl" scale="0.001 0.001 0.001" />
            </geometry>
        </collision>
    </link>
    <link name="arm_03_link_05_1">
        <inertial>
            <origin rpy="0 0 0" xyz="-0.016214862201250943 -1.9985843402459125e-07 -0.03500345629344043" />
            <mass value="0.6881065314959485" />
            <inertia ixx="0.002005" ixy="-0.0" ixz="0.000344" iyy="0.001936" iyz="-0.0" izz="0.000767" />
        </inertial>
        <visual>
            <origin rpy="0 0 0" xyz="-0.0 -1.19068 -0.5046" />
            <geometry>
                <mesh filename="package://mario_so2_description/meshes/arm_03_link_05_1.stl" scale="0.001 0.001 0.001" />
            </geometry>
            <material name="silver" />
        </visual>
        <collision>
            <origin rpy="0 0 0" xyz="-0.0 -1.19068 -0.5046" />
            <geometry>
                <mesh filename="package://mario_so2_description/meshes/arm_03_link_05_1.stl" scale="0.001 0.001 0.001" />
            </geometry>
        </collision>
    </link>
    <link name="arm_03_link_04_1">
        <inertial>
            <origin rpy="0 0 0" xyz="0.016104631094472653 -0.012232223653998897 -0.06928575048186703" />
            <mass value="0.702070494239485" />
            <inertia ixx="0.002018" ixy="6e-05" ixz="0.00034" iyy="0.00191" iyz="-0.000201" izz="0.000802" />
        </inertial>
        <visual>
            <origin rpy="0 0 0" xyz="-0.0 -1.209069 -0.608891" />
            <geometry>
                <mesh filename="package://mario_so2_description/meshes/arm_03_link_04_1.stl" scale="0.001 0.001 0.001" />
            </geometry>
            <material name="silver" />
        </visual>
        <collision>
            <origin rpy="0 0 0" xyz="-0.0 -1.209069 -0.608891" />
            <geometry>
                <mesh filename="package://mario_so2_description/meshes/arm_03_link_04_1.stl" scale="0.001 0.001 0.001" />
            </geometry>
        </collision>
    </link>
    <link name="arm_03_link_03_1">
        <inertial>
            <origin rpy="0 0 0" xyz="-0.021007560363102123 -0.01476773786261476 -0.08375416118603773" />
            <mass value="0.9974055974174089" />
            <inertia ixx="0.008725" ixy="0.000165" ixz="0.000936" iyy="0.008495" iyz="-0.001295" izz="0.00138" />
        </inertial>
        <visual>
            <origin rpy="0 0 0" xyz="-0.0064 -1.245257 -0.814125" />
            <geometry>
                <mesh filename="package://mario_so2_description/meshes/arm_03_link_03_1.stl" scale="0.001 0.001 0.001" />
            </geometry>
            <material name="silver" />
        </visual>
        <collision>
            <origin rpy="0 0 0" xyz="-0.0064 -1.245257 -0.814125" />
            <geometry>
                <mesh filename="package://mario_so2_description/meshes/arm_03_link_03_1.stl" scale="0.001 0.001 0.001" />
            </geometry>
        </collision>
    </link>
    <link name="arm_03_link_02_1">
        <inertial>
            <origin rpy="0 0 0" xyz="0.03418871169383212 0.08663667872544156 -0.18579266613747902" />
            <mass value="1.9698176425605938" />
            <inertia ixx="0.050345" ixy="-0.0" ixz="0.0" iyy="0.040774" iyz="0.018132" izz="0.010344" />
        </inertial>
        <visual>
            <origin rpy="0 0 0" xyz="-0.0064 -1.071984 -1.185711" />
            <geometry>
                <mesh filename="package://mario_so2_description/meshes/arm_03_link_02_1.stl" scale="0.001 0.001 0.001" />
            </geometry>
            <material name="silver" />
        </visual>
        <collision>
            <origin rpy="0 0 0" xyz="-0.0064 -1.071984 -1.185711" />
            <geometry>
                <mesh filename="package://mario_so2_description/meshes/arm_03_link_02_1.stl" scale="0.001 0.001 0.001" />
            </geometry>
        </collision>
    </link>
    <link name="arm_03_link_01_1">
        <inertial>
            <origin rpy="0 0 0" xyz="-0.013243511469967075 0.07075999158050561 -0.04085271223664955" />
            <mass value="0.7701153946406073" />
            <inertia ixx="0.002827" ixy="0.000283" ixz="-0.000163" iyy="0.001247" iyz="0.000849" izz="0.002227" />
        </inertial>
        <visual>
            <origin rpy="0 0 0" xyz="-0.001 -0.960786 -1.249911" />
            <geometry>
                <mesh filename="package://mario_so2_description/meshes/arm_03_link_01_1.stl" scale="0.001 0.001 0.001" />
            </geometry>
            <material name="silver" />
        </visual>
        <collision>
            <origin rpy="0 0 0" xyz="-0.001 -0.960786 -1.249911" />
            <geometry>
                <mesh filename="package://mario_so2_description/meshes/arm_03_link_01_1.stl" scale="0.001 0.001 0.001" />
            </geometry>
        </collision>
    </link>
    <link name="arm_03_link_00_1">
        <inertial>
            <origin rpy="0 0 0" xyz="1.2324126094642729e-14 0.06772308664672821 -0.03909956979495921" />
            <mass value="1.302064491206825" />
            <inertia ixx="0.003468" ixy="-0.0" ixz="0.0" iyy="0.002088" iyz="0.000797" izz="0.003008" />
        </inertial>
        <visual>
            <origin rpy="0 0 0" xyz="-0.001 -0.82534 -1.328111" />
            <geometry>
                <mesh filename="package://mario_so2_description/meshes/arm_03_link_00_1.stl" scale="0.001 0.001 0.001" />
            </geometry>
            <material name="silver" />
        </visual>
        <collision>
            <origin rpy="0 0 0" xyz="-0.001 -0.82534 -1.328111" />
            <geometry>
                <mesh filename="package://mario_so2_description/meshes/arm_03_link_00_1.stl" scale="0.001 0.001 0.001" />
            </geometry>
        </collision>
    </link>
    <joint name="arm_01_dock" self_collide="false" type="fixed">
        <origin rpy="0 0 0" xyz="0.0 0.0 0.0615" />
        <parent link="arm_01_link_06_1" />
        <child link="arm_01_dock_1" />
    </joint>
    <joint name="arm_01_joint_06" type="continuous">
        <origin rpy="0 0 0" xyz="0.0 0.0 0.1059" />
        <parent link="arm_01_link_05_1" />
        <child link="arm_01_link_06_1" />
        <axis xyz="0.0 0.0 1.0" />
    </joint>
    <joint name="arm_01_joint_05" type="continuous">
        <origin rpy="0 0 0" xyz="0.0 0.0 0.1059" />
        <parent link="arm_01_link_04_1" />
        <child link="arm_01_link_05_1" />
        <axis xyz="0.0 1.0 -0.0" />
    </joint>
    <joint name="arm_01_joint_04" type="continuous">
        <origin rpy="0 0 0" xyz="0.0 0.0064 0.2084" />
        <parent link="arm_01_link_03_1" />
        <child link="arm_01_link_04_1" />
        <axis xyz="0.0 0.0 1.0" />
    </joint>
    <joint name="arm_01_joint_03" type="continuous">
        <origin rpy="0 0 0" xyz="0.0 0.0 0.41" />
        <parent link="arm_01_link_02_1" />
        <child link="arm_01_link_03_1" />
        <axis xyz="0.0 1.0 -0.0" />
    </joint>
    <joint name="arm_01_joint_02" type="continuous">
        <origin rpy="0 0 0" xyz="0.0 -0.0054 0.1284" />
        <parent link="arm_01_link_01_1" />
        <child link="arm_01_link_02_1" />
        <axis xyz="0.0 1.0 -0.0" />
    </joint>
    <joint name="arm_01_joint_01" type="continuous">
        <origin rpy="0 0 0" xyz="0.0 0.0 0.1564" />
        <parent link="arm_01_link_00_1" />
        <child link="arm_01_link_01_1" />
        <axis xyz="0.0 0.0 1.0" />
    </joint>
    <joint name="arm_01_joint_base" type="fixed">
        <origin rpy="0 0 0" xyz="0.001 0.59534 1.726483" />
        <parent link="base_link" />
        <child link="arm_01_link_00_1" />
    </joint>
    <joint name="arm_02_dock" self_collide="false" type="fixed">
        <origin rpy="0 0 0" xyz="0.0 -0.0 -0.0615" />
        <parent link="arm_02_link_06_1" />
        <child link="arm_02_dock_1" />
    </joint>
    <joint name="arm_02_joint_06" type="continuous">
        <origin rpy="0 0 0" xyz="-0.0 0.0 -0.1059" />
        <parent link="arm_02_link_05_1" />
        <child link="arm_02_link_06_1" />
        <axis xyz="-0.0 -0.0 -1.0" />
    </joint>
    <joint name="arm_02_joint_05" type="continuous">
        <origin rpy="0 0 0" xyz="0.0 0.018389 -0.104291" />
        <parent link="arm_02_link_04_1" />
        <child link="arm_02_link_05_1" />
        <axis xyz="-1.0 0.0 0.0" />
    </joint>
    <joint name="arm_02_joint_04" type="continuous">
        <origin rpy="0 0 0" xyz="-0.0064 0.036189 -0.205234" />
        <parent link="arm_02_link_03_1" />
        <child link="arm_02_link_04_1" />
        <axis xyz="-0.0 0.173648 -0.984808" />
    </joint>
    <joint name="arm_02_joint_03" type="continuous">
        <origin rpy="0 0 0" xyz="0.0 -0.173274 -0.371586" />
        <parent link="arm_02_link_02_1" />
        <child link="arm_02_link_03_1" />
        <axis xyz="-1.0 0.0 0.0" />
    </joint>
    <joint name="arm_02_joint_02" type="continuous">
        <origin rpy="0 0 0" xyz="0.0054 -0.111198 -0.0642" />
        <parent link="arm_02_link_01_1" />
        <child link="arm_02_link_02_1" />
        <axis xyz="-1.0 0.0 0.0" />
    </joint>
    <joint name="arm_02_joint_01" type="continuous">
        <origin rpy="0 0 0" xyz="0.0 -0.135446 -0.0782" />
        <parent link="arm_02_link_00_1" />
        <child link="arm_02_link_01_1" />
        <axis xyz="-0.0 -0.866025 -0.5" />
    </joint>
    <joint name="arm_02_joint_base" type="fixed">
        <origin rpy="0 0 0" xyz="0.001 0.36534 1.328111" />
        <parent link="base_link" />
        <child link="arm_02_link_00_1" />
    </joint>
    <joint name="arm_03_dock" self_collide="false" type="fixed">
        <origin rpy="0 0 0" xyz="0.59634 -0.2372 0.349422" />
        <parent link="arm_03_link_06_1" />
        <child link="arm_03_dock_1" />
    </joint>
    <joint name="arm_03_joint_06" type="continuous">
        <origin rpy="0 0 0" xyz="0.0 0.0 -0.1059" />
        <parent link="arm_03_link_05_1" />
        <child link="arm_03_link_06_1" />
        <axis xyz="-0.0 -0.0 -1.0" />
    </joint>
    <joint name="arm_03_joint_05" type="continuous">
        <origin rpy="0 0 0" xyz="0.0 -0.018389 -0.104291" />
        <parent link="arm_03_link_04_1" />
        <child link="arm_03_link_05_1" />
        <axis xyz="-1.0 -0.0 0.0" />
    </joint>
    <joint name="arm_03_joint_04" type="continuous">
        <origin rpy="0 0 0" xyz="-0.0064 -0.036188 -0.205234" />
        <parent link="arm_03_link_03_1" />
        <child link="arm_03_link_04_1" />
        <axis xyz="-0.0 -0.173648 -0.984808" />
    </joint>
    <joint name="arm_03_joint_03" type="continuous">
        <origin rpy="0 0 0" xyz="0.0 0.173273 -0.371586" />
        <parent link="arm_03_link_02_1" />
        <child link="arm_03_link_03_1" />
        <axis xyz="-1.0 -0.0 0.0" />
    </joint>
    <joint name="arm_03_joint_02" type="continuous">
        <origin rpy="0 0 0" xyz="0.0054 0.111198 -0.0642" />
        <parent link="arm_03_link_01_1" />
        <child link="arm_03_link_02_1" />
        <axis xyz="-1.0 -0.0 0.0" />
    </joint>
    <joint name="arm_03_joint_01" type="continuous">
        <origin rpy="0 0 0" xyz="0.0 0.135446 -0.0782" />
        <parent link="arm_03_link_00_1" />
        <child link="arm_03_link_01_1" />
        <axis xyz="-0.0 0.866025 -0.5" />
    </joint>
    <joint name="arm_03_joint_base" type="fixed">
        <origin rpy="0 0 0" xyz="0.001 0.82534 1.328111" />
        <parent link="base_link" />
        <child link="arm_03_link_00_1" />
    </joint>
</robot>

